<?xml version="1.0" encoding="utf-8"?>
<!-- =================================================================================== -->
<!-- |    This document was autogenerated by xacro from urdf/xacro/tb_sim_simple.urdf.xacro | -->
<!-- |    EDITING THIS FILE BY HAND IS NOT RECOMMENDED                                 | -->
<!-- =================================================================================== -->
<robot name="tb_sim">
  <!-- Define robot physical and appearance model-->
  <!-- Using dummy/roundly estimated number for inertia, friction model-->
  <!-- IMPROVE
  * More simplify robot mesh files to run faster
  * Add material and calculate precise inertia tensor
  * Modify the friction model to get nature physical interaction-->
  <!-- Define robot links and joints -->
  <link name="footprint"/>
  <joint name="footprint_joint" type="fixed">
    <origin rpy="0 0.0 0" xyz="0.0 0.0 -0.076"/>
    <parent link="base_link"/>
    <child link="footprint"/>
    <axis xyz="0 0 0"/>
  </joint>
  <link name="base_link">
    <inertial>
      <origin rpy="0.0 0.0 0.0" xyz="-0.15 0.0 0.01"/>
      <mass value="5.5"/>
      <inertia ixx="0.03158" ixy="0" ixz="0" iyy="0.04418" iyz="0" izz="0.069898"/>
    </inertial>
    <visual>
      <origin rpy="0 0 0" xyz="0 0 0"/>
      <geometry>
        <mesh filename="package://tb_description/meshes/base_link.STL"/>
      </geometry>
    </visual>
    <collision>
      <origin rpy="0 0 0" xyz="0 0 0"/>
      <geometry>
        <mesh filename="package://tb_description/meshes/base_link.STL"/>
      </geometry>
    </collision>
    <!-- Define material -->
  </link>
  <link name="wheel_left_link">
    <inertial>
      <mass value="0.2"/>
      <inertia ixx="0.00039792" ixy="0" ixz="0" iyy="0.00078467" iyz="0" izz="0.00039792"/>
    </inertial>
    <visual>
      <geometry>
        <mesh filename="package://tb_description/meshes/wheel_link.STL"/>
      </geometry>
      <material name="black"/>
    </visual>
    <collision>
      <geometry>
        <mesh filename="package://tb_description/meshes/wheel_link.STL"/>
      </geometry>
    </collision>
  </link>
  <joint name="wheel_left_joint" type="continuous">
    <origin rpy="0 0 0" xyz="0 0.165 0"/>
    <parent link="base_link"/>
    <child link="wheel_left_link"/>
    <axis xyz="0 1 0"/>
  </joint>
  <!-- Define material and friction parameters-->
  <link name="wheel_right_link">
    <inertial>
      <mass value="0.2"/>
      <inertia ixx="0.00039792" ixy="0" ixz="0" iyy="0.00078467" iyz="0" izz="0.00039792"/>
    </inertial>
    <visual>
      <geometry>
        <mesh filename="package://tb_description/meshes/wheel_link.STL"/>
      </geometry>
      <material name="black"/>
    </visual>
    <collision>
      <geometry>
        <mesh filename="package://tb_description/meshes/wheel_link.STL"/>
      </geometry>
    </collision>
  </link>
  <joint name="wheel_right_joint" type="continuous">
    <origin rpy="0 0 0" xyz="0 -0.165 0"/>
    <parent link="base_link"/>
    <child link="wheel_right_link"/>
    <axis xyz="0 1 0"/>
  </joint>
  <!-- Define material and friction parameters-->
  <link name="caster_link">
    <inertial>
      <origin rpy="0 0 0" xyz="-0.016859 0 -0.039"/>
      <mass value="0.12725"/>
      <inertia ixx="0.00013389" ixy="-3.291E-08" ixz="-5.4328E-05" iyy="0.00016302" iyz="-4.433E-08" izz="9.9804E-05"/>
    </inertial>
    <visual>
      <origin rpy="0 0 0" xyz="0 0 0"/>
      <geometry>
        <mesh filename="package://tb_description/meshes/caster_link.STL"/>
      </geometry>
    </visual>
    <collision>
      <origin rpy="0 0 0" xyz="0 0 0"/>
      <geometry>
        <mesh filename="package://tb_description/meshes/caster_link.STL"/>
      </geometry>
    </collision>
  </link>
  <joint name="caster_joint" type="continuous">
    <origin rpy="0 0 0" xyz="-0.32849 0 0.036"/>
    <parent link="base_link"/>
    <child link="caster_link"/>
    <axis xyz="0 0 1"/>
    <safety_controller k_velocity="0"/>
  </joint>
  <link name="caster_wheel_link">
    <inertial>
      <origin rpy="0 0 0" xyz="0 7.5E-05 0"/>
      <mass value="0.055271"/>
      <inertia ixx="2.6207E-05" ixy="0" ixz="0" iyy="4.8328E-05" iyz="0" izz="2.6207E-05"/>
    </inertial>
    <visual>
      <origin rpy="0 0 0" xyz="0 0 0"/>
      <geometry>
        <mesh filename="package://tb_description/meshes/caster_wheel_link.STL"/>
      </geometry>
    </visual>
    <collision>
      <origin rpy="0 0 0" xyz="0 0 0"/>
      <geometry>
        <mesh filename="package://tb_description/meshes/caster_wheel_link.STL"/>
      </geometry>
    </collision>
  </link>
  <joint name="caster_wheel_joint" type="continuous">
    <origin rpy="0 0 0" xyz="-0.039059 0 -0.075"/>
    <parent link="caster_link"/>
    <child link="caster_wheel_link"/>
    <axis xyz="0 1 0"/>
    <safety_controller k_velocity="0"/>
  </joint>
  <link name="tube_link">
    <inertial>
      <origin rpy="0 0 0" xyz="0.02 0 0.6"/>
      <mass value="2"/>
      <inertia ixx="0.2083333333" ixy="0.0" ixz="0.0" iyy="0.2083333333" iyz="0.0" izz="0.000905"/>
    </inertial>
    <visual>
      <origin rpy="0 0 0" xyz="0 0 0"/>
      <geometry>
        <mesh filename="package://tb_description/meshes/tube_link.STL"/>
      </geometry>
    </visual>
    <collision>
      <origin rpy="0 0 0" xyz="0 0 0"/>
      <geometry>
        <mesh filename="package://tb_description/meshes/tube_link.STL"/>
      </geometry>
    </collision>
  </link>
  <joint name="tube_joint" type="fixed">
    <origin rpy="0 -0.18326 0" xyz="-0.026814 0 0.083753"/>
    <parent link="base_link"/>
    <child link="tube_link"/>
    <axis xyz="0 0 0"/>
    <safety_controller k_velocity="0"/>
  </joint>
  <link name="display_link">
    <inertial>
      <origin rpy="0 0 0" xyz="0.02866 0.0042627 0.019125"/>
      <mass value="0.3"/>
      <inertia ixx="0.0015625" ixy="0" ixz="0" iyy="0.000625" iyz="0" izz="0.0010625"/>
    </inertial>
    <visual>
      <origin rpy="0 0 0" xyz="0 0 0"/>
      <geometry>
        <mesh filename="package://tb_description/meshes/display_link.STL"/>
      </geometry>
    </visual>
    <collision>
      <origin rpy="0 0 0" xyz="0 0 0"/>
      <geometry>
        <mesh filename="package://tb_description/meshes/display_link.STL"/>
      </geometry>
    </collision>
  </link>
  <joint name="neck_joint" type="continuous">
    <origin rpy="0 0 0" xyz="0.14191 0 1.1557"/>
    <parent link="tube_link"/>
    <child link="display_link"/>
    <axis xyz="0.0 1 0.0"/>
    <safety_controller k_velocity="0"/>
  </joint>
  <!-- Define sensors from xacro -->
  <!-- urdf format -->
  <!-- dummy camera link attached to the camera rigid body -->
  <link name="tele_camera_link">
    <visual>
      <geometry>
        <box size="0.01 0.01 0.01"/>
      </geometry>
    </visual>
    <collision>
      <geometry>
        <box size="0.01 0.01 0.01"/>
      </geometry>
    </collision>
    <inertial>
      <mass value="0.01"/>
      <inertia ixx="0" ixy="0" ixz="0" iyy="0" iyz="0" izz="0"/>
    </inertial>
  </link>
  <joint name="tele_camera_mount_joint" type="fixed">
    <origin rpy="0.0 0.0 0" xyz="0.05 0 0.11"/>
    <parent link="display_link"/>
    <child link="tele_camera_link"/>
  </joint>
  <link name="tele_optical_frame"/>
  <joint name="tele_optical_joint" type="fixed">
    <origin rpy="1.570795 3.14159 1.570795" xyz="0 0 0"/>
    <parent link="tele_camera_link"/>
    <child link="tele_optical_frame"/>
  </joint>
  <gazebo reference="tele_camera_link">
    <sensor name="tele_camera" type="camera">
      <update_rate>30</update_rate>
      <camera>
        <horizontal_fov>2.09439</horizontal_fov>
        <image>
          <width>640</width>
          <height>480</height>
          <format>R8G8B8</format>
        </image>
        <clip>
          <near>0.01</near>
          <far>20</far>
        </clip>
        <noise>
          <type>gaussian</type>
          <!-- Noise is sampled independently per pixel on each frame.
                  That pixel's noise value is added to each of its color
                  channels, which at that point lie in the range [0,1]. -->
          <mean>0.0</mean>
          <stddev>0.007</stddev>
        </noise>
      </camera>
      <plugin filename="libgazebo_ros_camera.so" name="camera_plugin">
        <alwaysOn>true</alwaysOn>
        <updateRate>0.0</updateRate>
        <cameraName>tele_camera</cameraName>
        <imageTopicName>image_raw</imageTopicName>
        <cameraInfoTopicName>camera_info</cameraInfoTopicName>
        <frameName>tele_optical_frame</frameName>
        <hackBaseline>0.07</hackBaseline>
        <distortionK1>0.0</distortionK1>
        <distortionK2>0.0</distortionK2>
        <distortionK3>0.0</distortionK3>
        <distortionT1>0.0</distortionT1>
        <distortionT2>0.0</distortionT2>
      </plugin>
    </sensor>
  </gazebo>
  <!-- urdf format -->
  <!-- dummy camera link attached to the camera rigid body -->
  <link name="nav_camera_link">
    <visual>
      <geometry>
        <box size="0.01 0.01 0.01"/>
      </geometry>
    </visual>
    <collision>
      <geometry>
        <box size="0.01 0.01 0.01"/>
      </geometry>
    </collision>
    <inertial>
      <mass value="0.01"/>
      <inertia ixx="0" ixy="0" ixz="0" iyy="0" iyz="0" izz="0"/>
    </inertial>
  </link>
  <joint name="nav_camera_mount_joint" type="fixed">
    <origin rpy="0.0 1.39626222222 0" xyz="0.05 0 1.1"/>
    <parent link="tube_link"/>
    <child link="nav_camera_link"/>
  </joint>
  <link name="nav_optical_frame"/>
  <joint name="nav_optical_joint" type="fixed">
    <origin rpy="1.570795 3.14159 1.570795" xyz="0 0 0"/>
    <parent link="nav_camera_link"/>
    <child link="nav_optical_frame"/>
  </joint>
  <!-- urdf format -->
  <link name="depthcam_link">
    <visual>
      <geometry>
        <!-- <mesh filename="package://tb_description/meshes/sensors/kinect.dae"/> -->
        <box size="0.01 0.01 0.01"/>
      </geometry>
    </visual>
    <collision>
      <geometry>
        <!-- <box size="0.07 0.3 0.09"/> -->
        <box size="0.01 0.01 0.01"/>
      </geometry>
    </collision>
    <inertial>
      <mass value="0.01"/>
      <inertia ixx="0" ixy="0" ixz="0" iyy="0" iyz="0" izz="0"/>
    </inertial>
  </link>
  <joint name="depthcam_mount_joint" type="fixed">
    <origin rpy="0.0 0.872663888889 0" xyz="0.05 0 0.9"/>
    <parent link="tube_link"/>
    <!--<parent link="base_link"/>-->
    <child link="depthcam_link"/>
  </joint>
  <link name="depthcam_optical_frame"/>
  <joint name="depthcam_optical_joint" type="fixed">
    <origin rpy="1.570795 3.14159 1.570795" xyz="0 0 0"/>
    <parent link="depthcam_link"/>
    <child link="depthcam_optical_frame"/>
  </joint>
  <!-- urdf format -->
  <link name="imu_base_frame"/>
  <joint name="imu_base_mount_joint" type="fixed">
    <origin rpy="0.0 0.0 0" xyz="0 0 0"/>
    <parent link="base_link"/>
    <child link="imu_base_frame"/>
  </joint>
  <!-- urdf format -->
  <link name="laser_range_link">
    <visual>
      <geometry>
        <box size="0.01 0.01 0.01"/>
      </geometry>
    </visual>
    <collision>
      <geometry>
        <box size="0.01 0.01 0.01"/>
      </geometry>
    </collision>
    <inertial>
      <mass value="0.01"/>
      <inertia ixx="0" ixy="0" ixz="0" iyy="0" iyz="0" izz="0"/>
    </inertial>
  </link>
  <joint name="laser_range_mount_joint" type="fixed">
    <origin rpy="0.0 0.0 0" xyz="-0.3 0 0.2"/>
    <parent link="base_link"/>
    <child link="laser_range_link"/>
  </joint>
</robot>